Based on the provided content, here's a breakdown of the vulnerability:

**Root Cause:**

The vulnerability stems from missing checks in the `tensorflow/core/framework/function.cc` file when instantiating functions. Specifically, assertions (DCHECK) were used to verify that the `arg_index` is equal to `result_.nodes.size()` but these checks were not robust enough to handle malicious input. By crafting a `SavedModel` that violates these assumptions, an attacker could trigger a `CHECK`-fail, leading to a crash of the Python interpreter.

**Weaknesses/Vulnerabilities:**

*   **Missing Input Validation:** The code lacked proper validation of the `SavedModel` structure, particularly how function arguments are handled during instantiation.
*   **Use of Assertions for Security Checks:** Assertions (`DCHECK`) are meant for debugging and are typically not compiled in release builds. Relying on them for security-critical checks is a vulnerability.
*  **Incorrect assumption about dtypes size**: It was assumed that dtypes.size() was always >=1, which is not true in all cases.

**Impact of Exploitation:**

*   **Denial of Service (DoS):** A successful exploit results in the Python interpreter crashing, effectively halting the execution of the TensorFlow program.

**Attack Vectors:**

*   **Malicious `SavedModel`:** An attacker can craft a specially designed `SavedModel` file that contains a function definition that violates the assumptions made in `function.cc` during instantiation.

**Required Attacker Capabilities/Position:**

*   **Ability to provide input to a TensorFlow program:** The attacker needs to be able to supply the malicious `SavedModel` to a TensorFlow application. This could involve tricking a user into loading a malicious model or exploiting a vulnerability that allows the injection of such models.

**Additional Notes**

* The fix involves replacing the `DCHECK` with a proper error check, which returns a more descriptive error: `"Expected arg_index to be equal to the number of nodes in result. Got X and Y"`.
*   The vulnerability was patched in TensorFlow versions 2.5.3, 2.6.3, and 2.7.1. The fix is also included in version 2.8.0.
*   The vulnerability is classified as moderate severity.
*   The code commits related to the fix are `dcc21c7bc972b10b6fb95c2fb0f4ab5a59680ec2` and `3d89911481ba6ebe8c88c1c0b595412121e6c645`.
* The fix also adds a check `if (dtypes.size() < size_t{1}) { return errors::Internal("Expected a list of at least one dtype"); }`