Based on the provided content, here's a breakdown of CVE-2010-3492:

**Root Cause of Vulnerability:**

*   The root cause is a deficiency in the implementation of Python's `accept()` routine within the `asyncore` module. The `accept()` method could return `None` instead of a socket pair, raise `ECONNABORTED` or `EAGAIN` errors, or return a `None` address, all of which were not properly handled by user code.
*   The design of `asyncore` forces users to override `handle_accept()` and then call `self.accept()`.  This exposes the user to potential errors/unexpected returns from `accept()`.

**Weaknesses/Vulnerabilities Present:**

*   **Inadequate API documentation:** The primary issue is that the `asyncore` module's `accept()` method does not clearly document all the possible return values and exceptions. This forces users to implement their own error handling logic, increasing the risk of bugs.
*   **Error handling:** The `accept()` method could return `None`, raise exceptions like `TypeError`, `ECONNABORTED`, and `EAGAIN`, or have a `None` address in some cases. The `asyncore` documentation and the API did not make it clear to users that these edge cases needed to be explicitly handled.

**Impact of Exploitation:**

*   Applications using `asyncore` could fail to properly accept connections, potentially leading to denial-of-service or unexpected behavior if they did not handle the errors and unusual return values correctly.
*   Specific examples included applications that would raise an exception or return without handling the incoming connection.

**Attack Vectors:**

*   The attack vector primarily involves clients attempting to connect to an `asyncore`-based server in a way that triggers the unusual return values and exceptions from the `accept()` method. This could be done by:
    *   Hammering the server with tools like `nmap`.
    *   Sending many connection requests.
    *   Abruptly closing connections.

**Required Attacker Capabilities/Position:**

*   The attacker needs to be able to connect to a network service that is implemented using the affected Python asyncore library. No special privileges or access is required, as the attack would be via standard network communication.

**Additional Details:**

*   The issue affects Python versions 2.7, 3.1, and 3.2.
*   The vulnerability was addressed by:
    *   Modifying the `accept()` method to return `None` when no connection takes place or in cases of errors like `ECONNABORTED`, and updating the documentation.
    *   Adding a `handled_accepted()` method to the dispatcher class.
*   The fix involved both changes to the Python code and improvements in the documentation.
*   The following CVEs were assigned for specific applications using the flawed `asyncore.accept()` implementation:
    *   CVE-2010-3493 - `smtpd.py` not catching errors generated by `handle_accept`
    *   CVE-2010-3494 - `pyftpdlib` not catching errors generated by `handle_accept`
    *  CVE-2010-3495 - ZODB not catching errors generated by `handle_accept`
*   The bug report on the Python bug tracker [https://bugs.python.org/issue6706](https://bugs.python.org/issue6706) provides a detailed discussion, including links to external bug reports that were discovered as a result of the flawed implementation.