Based on the provided content, here's an analysis of the vulnerability related to Python's `accept()` implementation in the `asyncore` module:

**Root Cause of Vulnerability:**

The root cause is a combination of factors:
1.  **Inconsistent `accept()` behavior:** The `accept()` method in Python's `asyncore` module could return `None` under certain conditions (e.g., high load, specific OS behaviors when a connection is reset quickly), instead of a socket pair, leading to `TypeError` exceptions in user code that expects a tuple. Also, `accept()` could raise `ECONNABORTED` or `EAGAIN` errors, or return a socket with a `None` address.
2.  **Lack of explicit documentation:** The `asyncore` module's documentation did not clearly specify these potential return values and error conditions.
3.  **Incorrect Usage:** Application developers using `asyncore` were not always catching these exceptions, leading to crashes or other unexpected behavior.

**Weaknesses/Vulnerabilities Present:**
*   **API Design Flaw:** The `asyncore` API design forced users to directly call `accept()`, exposing them to low-level socket errors and return values, instead of abstracting this process.
*   **Missing Documentation:**  The absence of clear documentation regarding the various potential outcomes of `accept()` made it difficult for developers to handle them correctly, especially under stress situations.

**Impact of Exploitation:**
*   **Denial of Service (DoS):** By sending specific network traffic (e.g., using `nmap` or quickly resetting connections), an attacker could trigger the conditions causing `accept()` to fail, leading to exceptions and potentially crashing the server application.
*   **Unexpected server behavior:** Without proper handling of the different failure modes of `accept()`, server applications could become non-responsive or behave erratically when under load.
*   **Information Exposure**: Although not explicitly stated, a failure to handle the lack of connection information could lead to unexpected behavior when trying to access properties of the connection that do not exist.

**Attack Vectors:**
*   **Network-based attacks:** An attacker could exploit the inconsistent `accept()` behavior by sending malformed or unexpected network traffic to the server.
*   **Load-based attacks:** An attacker can overwhelm the server with connection attempts causing `accept()` to fail.

**Required Attacker Capabilities/Position:**
*   **Network access:** The attacker needs to be able to send network traffic to the vulnerable server.
*   **Moderate network control:** To trigger the issue effectively, the attacker might need the ability to create and reset connections quickly.

**Additional Notes:**
*   The vulnerability was primarily related to how `asyncore` handled connection events, not with a flaw in the operating system's socket handling. The OS might be behaving according to specifications, but the Python API didn't provide enough information or proper abstraction.
*   The fix involved a combination of code changes and documentation updates, namely suppressing `EWOULDBLOCK/ECONNABORTED` errors, returning `None` instead, and clarifying the proper usage of `handle_accept()`. A new method `handle_accepted()` was added to allow users to handle accepted connections without directly calling accept().
*   The issue affected multiple projects (e.g., `smtpd.py`, `pyftpdlib`, and `ZODB`) that relied on the flawed `asyncore` API.

The content provides more details than a standard CVE description. It includes discussions on different ways to resolve the issue, code snippets of the fix, and reproduction steps for the vulnerability.