```
{
  "CVE-2023-26052": {
    "related": true,
    "summary": "The application does not properly handle internal Python exceptions, which can lead to sensitive information disclosure in API error messages to unauthenticated users.",
    "details": {
      "root_cause": "Internal Python exceptions are not properly handled, resulting in their exposure through API error messages.",
      "vulnerabilities": [
        "Information Disclosure"
      ],
      "impact": "Exposure of sensitive information, such as infrastructure details, to unauthenticated users.",
      "attack_vectors": [
        "Network - Attacker sends unauthenticated API requests that trigger unhandled Python exceptions"
       ],
      "attacker_capabilities": "The attacker does not need any privileges or user interaction.",
      "affected_versions": "Saleor versions 2.0.0 and later before patched versions.",
        "patched_versions": [
          "3.11.12",
          "3.10.14",
          "3.9.27",
          "3.8.30",
          "3.7.59",
          "3.1.48"
        ],
       "cwe":"CWE-209"
    }
  }
}
```