Based on the provided content, here's an analysis of the vulnerability:

**Root Cause of Vulnerability:**

*   The root cause is the presence of a malicious backdoor within the `request` package that was included in versions 0.1 to 0.13 of the `marcador` project. This malicious `request` package allowed for arbitrary code execution.

**Weaknesses/Vulnerabilities Present:**

*   **Supply Chain Vulnerability:** The vulnerability is introduced via a malicious dependency. The affected project, `marcador`, depended on a compromised `request` package.
*   **Backdoor:** The malicious `request` package contained a backdoor, allowing attackers to execute arbitrary code on systems where `marcador` was installed.

**Impact of Exploitation:**

*   **Arbitrary Code Execution:** An attacker could execute arbitrary code on the victim's machine by installing a vulnerable version of `marcador`.
*   **System Compromise:** The arbitrary code execution could lead to full system compromise depending on the permissions of the user running the code, allowing for data theft, further malware installation, and other malicious activities.

**Attack Vectors:**

*   **Compromised Package Mirrors:** The attacker leveraged compromised mirrors of the PyPI repository to distribute the malicious `request` package. Specifically, the `pypi.doubanio.com` mirror was mentioned.
*   **Dependency Installation:** The vulnerability was triggered when users installed the compromised versions (0.1-0.13) of the `marcador` package, and because of that indirectly installing the malicious dependency.

**Required Attacker Capabilities/Position:**

*   **Ability to Compromise Package Mirrors:** The attacker needs the ability to insert the malicious `request` package on a PyPI mirror.
*   **Victim Install Specific Version:** The victim needs to install the compromised versions (0.1 to 0.13) of the `marcador` package to be vulnerable.

**Additional details:**

*   The issue was reported on the GitHub repository of the `marcador` project.
*   The maintainer of `marcador` was made aware of the issue, and the vulnerable versions were removed from PyPI.
*   However, the malicious package might still exist on some mirrors, as pointed out in the issue.